<?xml version="1.0"?>
<!-- =================================================================================== -->
<!-- |    This document was autogenerated by xacro from ur5e.xacro                     | -->
<!-- |    EDITING THIS FILE BY HAND IS NOT RECOMMENDED                                 | -->
<!-- =================================================================================== -->
<robot name="xarm_lite6">

  <!-- links: main serial chain -->
  <link name="link_base" />
  <link name="link1" />
  <link name="link2" />
  <link name="link3" />
  <link name="link4" />
  <link name="link5" />
  <link name="link6" />


  <!-- joints: main serial chain -->
  <joint name="joint1" type="revolute">
    <origin xyz="0 0 0.2435" rpy="0 0 0" />
    <parent link="link_base" />
    <child link="link1" />
    <axis xyz="0 0 1" />
    <limit
      lower="-6.283185307"
      upper="6.283185307"
      effort="50.0"
      velocity="3.14" />
    <dynamics damping="1.0" friction="1.0" />
  </joint>

<joint name="joint2" type="revolute">
      <origin xyz="0 0 0" rpy="1.5708 -1.5708 3.1416" />
      <parent link="link1" />
      <child link="link2" />
      <axis xyz="0 0 1" />
      <limit
        lower="-2.61799"
        upper="2.61799"
        effort="50.0"
        velocity="3.14"/>
      <dynamics damping="1.0" friction="1.0"/>
    </joint>

<joint name="joint3" type="revolute">
      <origin xyz="0.2002 0 0" rpy="-3.1416 0 1.5708" />
      <parent link="link2" />
      <child link="link3" />
      <axis xyz="0 0 1" />
      <limit
        lower="-0.061087"
        upper="5.235988"
        effort="32.0"
        velocity="3.14"/>
      <dynamics damping="1.0" friction="1.0"/>
    </joint>

<joint name="joint4" type="revolute">
      <origin xyz="0.087 -0.22761 0" rpy="1.5708 0 0" />
      <parent link="link3" />
      <child link="link4" />
      <axis xyz="0 0 1" />
      <limit
        lower="-6.283185307"
        upper="6.283185307"
        effort="32.0"
        velocity="3.14"/>
      <dynamics damping="1.0" friction="1.0"/>
    </joint>

<joint name="joint5" type="revolute">
      <origin xyz="0 0 0" rpy="1.5708 0 0" />
      <parent link="link4" />
      <child link="link5" />
      <axis xyz="0 0 1" />
      <limit
        lower="-2.1642"
        upper="2.1642"
        effort="32.0"
        velocity="3.14"/>
      <dynamics damping="1.0" friction="1.0"/>
    </joint>

<joint name="joint6" type="revolute">
      <origin xyz="0 0.0625 0" rpy="-1.5708 0 0" />
      <parent link="link5" />
      <child link="link6" />
      <axis xyz="0 0 1" />
      <limit
        lower="-6.283185307"
        upper="6.283185307"
        effort="20.0"
        velocity="3.14"/>
      <dynamics damping="1.0" friction="1.0"/>
    </joint>


</robot>